Workbook

Sheet Introduction
B2: 00. System configuration
B4: ENLIGHT | J4: Version: | K4: 1
B23: 1.1 Contact Persons
E25: E-mail: | H25: Telephone:
B26: Marco Saretta | E26: MCSR@ramboll.com | H26: 0045 60361204
B27: Søren Møller Thomsen | E27: SMT@ramboll.com | H27: 0045 51612421

Sheet Project setup
C2: Project setup
C5: Project timeline
D8: label | E8: key | F8: format | G8: unit | H8: scenario_1 | I8: scenario_2 | J8: scenario_3 | K8: scenario_4 | L8: scenario_5 | M8: scenario_6 | N8: scenario_7 | O8: scenario_8 | P8: scenario_9 | Q8: scenario_10
B9: Prediction year | D9: SETUP | E9: prediction_year | F9: int | G9: Year | H9: 2040 | I9: 2040 | J9: 2040 | K9: =J9 -> 2040
C11: Wind generation
B13: 2.1.0 | C13: Onshore wind
D15: label | E15: key | F15: format | G15: unit | H15: scenario_1 | I15: scenario_2 | J15: scenario_3 | K15: scenario_4 | L15: scenario_5 | M15: scenario_6 | N15: scenario_7 | O15: scenario_8 | P15: scenario_9 | Q15: scenario_10
B16: Weather year | D16: WIND_ON | E16: wind_onshore_wy | F16: int | G16: Year | H16: 2020 | I16: 2021 | J16: 2023 | K16: 2024
B17: Capacity projection file | D17: WIND_ON | E17: wind_onshore_cap_file | F17: str | G17: - | H17: TYNDP_2024_National_Trends | I17: TYNDP_2024_National_Trends | J17: TYNDP_2024_National_Trends | K17: TYNDP_2024_National_Trends
B18: Bid price | D18: WIND_ON | E18: wind_onshore_bid_price | F18: float | H18: 0.01 | I18: =H18 -> 0.01 | J18: =I18 -> 0.01 | K18: =J18 -> 0.01
B20: 2.1.0 | C20: Offshore wind
D22: label | E22: key | F22: format | G22: unit | H22: scenario_1 | I22: scenario_2 | J22: scenario_3 | K22: scenario_4 | L22: scenario_5 | M22: scenario_6 | N22: scenario_7 | O22: scenario_8 | P22: scenario_9 | Q22: scenario_10
B23: Weather year | D23: WIND_OFF | E23: wind_offshore_wy | F23: int | G23: Year | H23: 2020 | I23: 2021 | J23: 2023 | K23: 2024
B24: Capacity projection file | D24: WIND_OFF | E24: wind_offshore_cap_file | F24: str | G24: - | H24: TYNDP_2024_National_Trends | I24: TYNDP_2024_National_Trends | J24: TYNDP_2024_National_Trends | K24: TYNDP_2024_National_Trends
B25: Bid price | D25: WIND_OFF | E25: wind_offshore_bid_price | F25: float | G25: EUR/MWh | H25: 0.02 | I25: =H25 -> 0.02 | J25: =I25 -> 0.02 | K25: =J25 -> 0.02
C27: Solar PV
D29: label | E29: key | F29: format | G29: unit | H29: scenario_1 | I29: scenario_2 | J29: scenario_3 | K29: scenario_4 | L29: scenario_5 | M29: scenario_6 | N29: scenario_7 | O29: scenario_8 | P29: scenario_9 | Q29: scenario_10
B30: Weather year | D30: SOLAR | E30: solar_pv_wy | F30: int | G30: Year | H30: 2020 | I30: 2021 | J30: 2023 | K30: 2024
B31: Capacity projection file | D31: SOLAR | E31: solar_pv_cap_file | F31: str | G31: - | H31: TYNDP_2024_National_Trends | I31: TYNDP_2024_National_Trends | J31: TYNDP_2024_National_Trends | K31: TYNDP_2024_National_Trends
B32: Bid price | D32: SOLAR | E32: solar_pv_bid_price | F32: float | G32: EUR/MWh | H32: 0.03 | I32: =H32 -> 0.03 | J32: =I32 -> 0.03 | K32: =J32 -> 0.03
C34: Hydro power
C36: Run of river
D38: label | E38: key | F38: format | G38: unit | H38: scenario_1 | I38: scenario_2 | J38: scenario_3 | K38: scenario_4 | L38: scenario_5 | M38: scenario_6 | N38: scenario_7 | O38: scenario_8 | P38: scenario_9 | Q38: scenario_10
B39: Weather year | D39: HYDRO_ROR | E39: hydro_ror_wy | F39: int | G39: Year | H39: 2020 | I39: 2021 | J39: 2023 | K39: 2024
B40: Capacity expansion file | D40: HYDRO_ROR | E40: hydro_ror_cap_file | F40: str | G40: - | H40: TYNDP_2024_National_Trends | I40: TYNDP_2024_National_Trends | J40: TYNDP_2024_National_Trends | K40: TYNDP_2024_National_Trends
B41: Bid price | D41: HYDRO_ROR | E41: hydro_ror_bid_price | F41: float | G41: EUR/MWh | H41: 0.04 | I41: =H41 -> 0.04 | J41: =I41 -> 0.04 | K41: =J41 -> 0.04
C43: Reservoir hydro
D45: label | E45: key | F45: format | G45: unit | H45: scenario_1 | I45: scenario_2 | J45: scenario_3 | K45: scenario_4 | L45: scenario_5 | M45: scenario_6 | N45: scenario_7 | O45: scenario_8 | P45: scenario_9 | Q45: scenario_10
B46: Reservoir hydro units file | D46: HYDRO_RES | E46: hydro_res_units_file | F46: float | G46: % | H46: hydro_reservoir_units | I46: hydro_reservoir_units | J46: hydro_reservoir_units | K46: hydro_reservoir_units
B47: Energy availability weather year | D47: HYDRO_RES | E47: hydro_res_energy_wy | F47: float | G47: % | H47: 2020 | I47: 2021 | J47: 2023 | K47: 2024
B48: Fuel price projection | D48: HYDRO_RES | E48: hydro_res_bid_price | F48: str | G48: - | H48: ramboll | I48: ramboll | J48: ramboll | K48: ramboll
C50: Pumped hydro
D52: label | E52: key | F52: format | G52: unit | H52: scenario_1 | I52: scenario_2 | J52: scenario_3 | K52: scenario_4 | L52: scenario_5 | M52: scenario_6 | N52: scenario_7 | O52: scenario_8 | P52: scenario_9 | Q52: scenario_10
B53: Pumped hydro storage file | D53: HYDRO_PS | E53: hydro_ps_units_file | F53: float | G53: - | H53: hydro_pumped_storage_units | I53: hydro_pumped_storage_units | J53: hydro_pumped_storage_units | K53: hydro_pumped_storage_units
B54: Initial state-of-charge | D54: HYDRO_PS | E54: hydro_ps_initial_soc | F54: float | G54: - | H54: 0.5 | I54: 0.5 | J54: 0.5 | K54: 0.5
B55: Roundtrip efficiency | D55: HYDRO_PS | E55: hydro_ps_roundtrip | F55: float | G55: - | H55: 0.9 | I55: 0.9 | J55: 0.9 | K55: 0.9
B56: Fuel price projection | D56: HYDRO_PS | E56: hydro_ph_fuel_proj | F56: str | G56: - | H56: ramboll | I56: ramboll | J56: ramboll | K56: ramboll
C58: Thermal generators
D60: label | E60: key | F60: format | G60: unit | H60: scenario_1 | I60: scenario_2 | J60: scenario_3 | K60: scenario_4 | L60: scenario_5 | M60: scenario_6 | N60: scenario_7 | O60: scenario_8 | P60: scenario_9 | Q60: scenario_10
B61: Thermal units file | D61: THERMAL | E61: thermal_units_file | F61: str | G61: - | H61: thermal_plant_units | I61: thermal_plant_units | J61: thermal_plant_units | K61: thermal_plant_units
...

Sheet Python
A1: ='Project setup'!D8 -> label | B1: ='Project setup'!E8 -> key | C1: ='Project setup'!F8 -> format | D1: ='Project setup'!G8 -> unit | E1: ='Project setup'!H8 -> scenario_1 | F1: ='Project setup'!I8 -> scenario_2 | G1: ='Project setup'!J8 -> scenario_3 | H1: ='Project setup'!K8 -> scenario_4 | ... N1: ='Project setup'!Q8 -> scenario_10
A2: ='Project setup'!D9 -> SETUP | B2: ='Project setup'!E9 -> prediction_year | C2: ='Project setup'!F9 -> int | D2: ='Project setup'!G9 -> Year | E2: ='Project setup'!H9 -> 2040 | F2: ='Project setup'!I9 -> 2040 | G2: ='Project setup'!J9 -> 2040 | H2: ='Project setup'!K9 -> 2040 | ... N2: ='Project setup'!Q9 -> 0
A3: ='Project setup'!D16 -> WIND_ON | B3: ='Project setup'!E16 -> wind_onshore_wy | C3: ='Project setup'!F16 -> int | D3: ='Project setup'!G16 -> Year | E3: ='Project setup'!H16 -> 2020 | F3: ='Project setup'!I16 -> 2021 | G3: ='Project setup'!J16 -> 2023 | H3: ='Project setup'!K16 -> 2024 | ... N3: ='Project setup'!Q16 -> 0
A4: ='Project setup'!D17 -> WIND_ON | B4: ='Project setup'!E17 -> wind_onshore_cap_file | C4: ='Project setup'!F17 -> str | D4: ='Project setup'!G17 -> - | E4: ='Project setup'!H17 -> TYNDP_2024_National_Trends | F4: ='Project setup'!I17 -> TYNDP_2024_National_Trends | G4: ='Project setup'!J17 -> TYNDP_2024_National_Trends | H4: ='Project setup'!K17 -> TYNDP_2024_National_Trends | ... N4: ='Project setup'!Q17 -> 0
A5: ='Project setup'!D18 -> WIND_ON | B5: ='Project setup'!E18 -> wind_onshore_bid_price | C5: ='Project setup'!F18 -> float | D5: ='Project setup'!G18 | E5: ='Project setup'!H18 -> 0.01 | F5: ='Project setup'!I18 -> 0.01 | G5: ='Project setup'!J18 -> 0.01 | H5: ='Project setup'!K18 -> 0.01 | ... N5: ='Project setup'!Q18 -> 0
A6: ='Project setup'!D23 -> WIND_OFF | B6: ='Project setup'!E23 -> wind_offshore_wy | C6: ='Project setup'!F23 -> int | D6: ='Project setup'!G23 -> Year | E6: ='Project setup'!H23 -> 2020 | F6: ='Project setup'!I23 -> 2021 | G6: ='Project setup'!J23 -> 2023 | H6: ='Project setup'!K23 -> 2024 | ... N6: ='Project setup'!Q23 -> 0
A7: ='Project setup'!D24 -> WIND_OFF | B7: ='Project setup'!E24 -> wind_offshore_cap_file | C7: ='Project setup'!F24 -> str | D7: ='Project setup'!G24 -> - | E7: ='Project setup'!H24 -> TYNDP_2024_National_Trends | F7: ='Project setup'!I24 -> TYNDP_2024_National_Trends | G7: ='Project setup'!J24 -> TYNDP_2024_National_Trends | H7: ='Project setup'!K24 -> TYNDP_2024_National_Trends | ... N7: ='Project setup'!Q24 -> 0
A8: ='Project setup'!D25 -> WIND_OFF | B8: ='Project setup'!E25 -> wind_offshore_bid_price | C8: ='Project setup'!F25 -> float | D8: ='Project setup'!G25 -> EUR/MWh | E8: ='Project setup'!H25 -> 0.02 | F8: ='Project setup'!I25 -> 0.02 | G8: ='Project setup'!J25 -> 0.02 | H8: ='Project setup'!K25 -> 0.02 | ... N8: ='Project setup'!Q25 -> 0
A9: ='Project setup'!D30 -> SOLAR | B9: ='Project setup'!E30 -> solar_pv_wy | C9: ='Project setup'!F30 -> int | D9: ='Project setup'!G30 -> Year | E9: ='Project setup'!H30 -> 2020 | F9: ='Project setup'!I30 -> 2021 | G9: ='Project setup'!J30 -> 2023 | H9: ='Project setup'!K30 -> 2024 | ... N9: ='Project setup'!Q30 -> 0
A10: ='Project setup'!D31 -> SOLAR | B10: ='Project setup'!E31 -> solar_pv_cap_file | C10: ='Project setup'!F31 -> str | D10: ='Project setup'!G31 -> - | E10: ='Project setup'!H31 -> TYNDP_2024_National_Trends | F10: ='Project setup'!I31 -> TYNDP_2024_National_Trends | G10: ='Project setup'!J31 -> TYNDP_2024_National_Trends | H10: ='Project setup'!K31 -> TYNDP_2024_National_Trends | ... N10: ='Project setup'!Q31 -> 0
A11: ='Project setup'!D32 -> SOLAR | B11: ='Project setup'!E32 -> solar_pv_bid_price | C11: ='Project setup'!F32 -> float | D11: ='Project setup'!G32 -> EUR/MWh | E11: ='Project setup'!H32 -> 0.03 | F11: ='Project setup'!I32 -> 0.03 | G11: ='Project setup'!J32 -> 0.03 | H11: ='Project setup'!K32 -> 0.03 | ... N11: ='Project setup'!Q32 -> 0
A12: ='Project setup'!D39 -> HYDRO_ROR | B12: ='Project setup'!E39 -> hydro_ror_wy | C12: ='Project setup'!F39 -> int | D12: ='Project setup'!G39 -> Year | E12: ='Project setup'!H39 -> 2020 | F12: ='Project setup'!I39 -> 2021 | G12: ='Project setup'!J39 -> 2023 | H12: ='Project setup'!K39 -> 2024 | ... N12: ='Project setup'!Q39 -> 0
A13: ='Project setup'!D40 -> HYDRO_ROR | B13: ='Project setup'!E40 -> hydro_ror_cap_file | C13: ='Project setup'!F40 -> str | D13: ='Project setup'!G40 -> - | E13: ='Project setup'!H40 -> TYNDP_2024_National_Trends | F13: ='Project setup'!I40 -> TYNDP_2024_National_Trends | G13: ='Project setup'!J40 -> TYNDP_2024_National_Trends | H13: ='Project setup'!K40 -> TYNDP_2024_National_Trends | ... N13: ='Project setup'!Q40 -> 0
A14: ='Project setup'!D41 -> HYDRO_ROR | B14: ='Project setup'!E41 -> hydro_ror_bid_price | C14: ='Project setup'!F41 -> float | D14: ='Project setup'!G41 -> EUR/MWh | E14: ='Project setup'!H41 -> 0.04 | F14: ='Project setup'!I41 -> 0.04 | G14: ='Project setup'!J41 -> 0.04 | H14: ='Project setup'!K41 -> 0.04 | ... N14: ='Project setup'!Q41 -> 0
A15: ='Project setup'!D46 -> HYDRO_RES | B15: ='Project setup'!E46 -> hydro_res_units_file | C15: ='Project setup'!F46 -> float | D15: ='Project setup'!G46 -> % | E15: ='Project setup'!H46 -> hydro_reservoir_units | F15: ='Project setup'!I46 -> hydro_reservoir_units | G15: ='Project setup'!J46 -> hydro_reservoir_units | H15: ='Project setup'!K46 -> hydro_reservoir_units | ... N15: ='Project setup'!Q46 -> 0
A16: ='Project setup'!D47 -> HYDRO_RES | B16: ='Project setup'!E47 -> hydro_res_energy_wy | C16: ='Project setup'!F47 -> float | D16: ='Project setup'!G47 -> % | E16: ='Project setup'!H47 -> 2020 | F16: ='Project setup'!I47 -> 2021 | G16: ='Project setup'!J47 -> 2023 | H16: ='Project setup'!K47 -> 2024 | ... N16: ='Project setup'!Q47 -> 0
A17: ='Project setup'!D48 -> HYDRO_RES | B17: ='Project setup'!E48 -> hydro_res_bid_price | C17: ='Project setup'!F48 -> str | D17: ='Project setup'!G48 -> - | E17: ='Project setup'!H48 -> ramboll | F17: ='Project setup'!I48 -> ramboll | G17: ='Project setup'!J48 -> ramboll | H17: ='Project setup'!K48 -> ramboll | ... N17: ='Project setup'!Q48 -> 0
A18: ='Project setup'!D53 -> HYDRO_PS | B18: ='Project setup'!E53 -> hydro_ps_units_file | C18: ='Project setup'!F53 -> float | D18: ='Project setup'!G53 -> - | E18: ='Project setup'!H53 -> hydro_pumped_storage_units | F18: ='Project setup'!I53 -> hydro_pumped_storage_units | G18: ='Project setup'!J53 -> hydro_pumped_storage_units | H18: ='Project setup'!K53 -> hydro_pumped_storage_units | ... N18: ='Project setup'!Q53 -> 0
A19: ='Project setup'!D54 -> HYDRO_PS | B19: ='Project setup'!E54 -> hydro_ps_initial_soc | C19: ='Project setup'!F54 -> float | D19: ='Project setup'!G54 -> - | E19: ='Project setup'!H54 -> 0.5 | F19: ='Project setup'!I54 -> 0.5 | G19: ='Project setup'!J54 -> 0.5 | H19: ='Project setup'!K54 -> 0.5 | ... N19: ='Project setup'!Q54 -> 0
A20: ='Project setup'!D55 -> HYDRO_PS | B20: ='Project setup'!E55 -> hydro_ps_roundtrip | C20: ='Project setup'!F55 -> float | D20: ='Project setup'!G55 -> - | E20: ='Project setup'!H55 -> 0.9 | F20: ='Project setup'!I55 -> 0.9 | G20: ='Project setup'!J55 -> 0.9 | H20: ='Project setup'!K55 -> 0.9 | ... N20: ='Project setup'!Q55 -> 0
A21: ='Project setup'!D56 -> HYDRO_PS | B21: ='Project setup'!E56 -> hydro_ph_fuel_proj | C21: ='Project setup'!F56 -> str | D21: ='Project setup'!G56 -> - | E21: ='Project setup'!H56 -> ramboll | F21: ='Project setup'!I56 -> ramboll | G21: ='Project setup'!J56 -> ramboll | H21: ='Project setup'!K56 -> ramboll | ... N21: ='Project setup'!Q56 -> 0
A22: ='Project setup'!D61 -> THERMAL | B22: ='Project setup'!E61 -> thermal_units_file | C22: ='Project setup'!F61 -> str | D22: ='Project setup'!G61 -> - | E22: ='Project setup'!H61 -> thermal_plant_units | F22: ='Project setup'!I61 -> thermal_plant_units | G22: ='Project setup'!J61 -> thermal_plant_units | H22: ='Project setup'!K61 -> thermal_plant_units | ... N22: ='Project setup'!Q61 -> 0
A23: ='Project setup'!D62 -> THERMAL | B23: ='Project setup'!E62 -> thermal_fuel_proj | C23: ='Project setup'!F62 -> str | D23: ='Project setup'!G62 -> - | E23: ='Project setup'!H62 -> ramboll | F23: ='Project setup'!I62 -> ramboll | G23: ='Project setup'!J62 -> ramboll | H23: ='Project setup'!K62 -> ramboll | ... N23: ='Project setup'!Q62 -> 0
A24: ='Project setup'!D67 -> LINES | B24: ='Project setup'!E67 -> line_cap_file | C24: ='Project setup'!F67 -> str | D24: ='Project setup'!G67 -> - | E24: ='Project setup'!H67 -> entsoe | F24: ='Project setup'!I67 -> entsoe | G24: ='Project setup'!J67 -> entsoe | H24: ='Project setup'!K67 -> entsoe | ... N24: ='Project setup'!Q67 -> 0
A25: ='Project setup'!D74 -> DEMAND_INF_CLA | B25: ='Project setup'!E74 -> demand_inf_cla_py | C25: ='Project setup'!F74 -> int | D25: ='Project setup'!G74 -> Year | E25: ='Project setup'!H74 -> 2020 | F25: ='Project setup'!I74 -> 2020 | G25: ='Project setup'!J74 -> 2020 | H25: ='Project setup'!K74 -> 2020 | ... N25: ='Project setup'!Q74 -> 0
A26: ='Project setup'!D75 -> DEMAND_INF_CLA | B26: ='Project setup'!E75 -> demand_inf_cla_amount_file | C26: ='Project setup'!F75 -> str | D26: ='Project setup'!G75 -> - | E26: ='Project setup'!H75 -> TYNDP_2024_National_Trends | F26: ='Project setup'!I75 -> TYNDP_2024_National_Trends | G26: ='Project setup'!J75 -> TYNDP_2024_National_Trends | H26: ='Project setup'!K75 -> TYNDP_2024_National_Trends | ... N26: ='Project setup'!Q75 -> 0
A27: ='Project setup'!D76 -> DEMAND_INF_CLA | B27: ='Project setup'!E76 -> demand_inf_cla_voll | C27: ='Project setup'!F76 -> float | D27: ='Project setup'!G76 -> EUR/MWh | E27: ='Project setup'!H76 -> 5000 | F27: ='Project setup'!I76 -> 5000 | G27: ='Project setup'!J76 -> 5000 | H27: ='Project setup'!K76 -> 5000 | ... N27: ='Project setup'!Q76 -> 0
A28: ='Project setup'!D81 -> DEMAND_INF_IND | B28: ='Project setup'!E81 -> demand_inf_ind_py | C28: ='Project setup'!F81 -> int | D28: ='Project setup'!G81 -> Year | E28: ='Project setup'!H81 -> 2020 | F28: ='Project setup'!I81 -> 2020 | G28: ='Project setup'!J81 -> 2020 | H28: ='Project setup'!K81 -> 2020 | ... N28: ='Project setup'!Q81 -> 0
A29: ='Project setup'!D82 -> DEMAND_INF_IND | B29: ='Project setup'!E82 -> demand_inf_ind_amount_file | C29: ='Project setup'!F82 -> str | D29: ='Project setup'!G82 -> - | E29: ='Project setup'!H82 -> TYNDP_2024_National_Trends | F29: ='Project setup'!I82 -> TYNDP_2024_National_Trends | G29: ='Project setup'!J82 -> TYNDP_2024_National_Trends | H29: ='Project setup'!K82 -> TYNDP_2024_National_Trends | ... N29: ='Project setup'!Q82 -> 0
A30: ='Project setup'!D83 -> DEMAND_INF_IND | B30: ='Project setup'!E83 -> demand_inf_ind_voll | C30: ='Project setup'!F83 -> float | D30: ='Project setup'!G83 -> EUR/MWh | E30: ='Project setup'!H83 -> 5001 | F30: ='Project setup'!I83 -> 5001 | G30: ='Project setup'!J83 -> 5001 | H30: ='Project setup'!K83 -> 5001 | ... N30: ='Project setup'!Q83 -> 0
A31: ='Project setup'!D88 -> DEMAND_INF_HOU | B31: ='Project setup'!E88 -> demand_inf_hou_py | C31: ='Project setup'!F88 -> int | D31: ='Project setup'!G88 -> Year | E31: ='Project setup'!H88 -> 2020 | F31: ='Project setup'!I88 -> 2020 | G31: ='Project setup'!J88 -> 2020 | H31: ='Project setup'!K88 -> 2020 | ... N31: ='Project setup'!Q88 -> 0
A32: ='Project setup'!D89 -> DEMAND_INF_HOU | B32: ='Project setup'!E89 -> demand_inf_hou_amount_file | C32: ='Project setup'!F89 -> str | D32: ='Project setup'!G89 -> - | E32: ='Project setup'!H89 -> TYNDP_2024_National_Trends | F32: ='Project setup'!I89 -> TYNDP_2024_National_Trends | G32: ='Project setup'!J89 -> TYNDP_2024_National_Trends | H32: ='Project setup'!K89 -> TYNDP_2024_National_Trends | ... N32: ='Project setup'!Q89 -> 0
A33: ='Project setup'!D90 -> DEMAND_INF_HOU | B33: ='Project setup'!E90 -> demand_inf_hou_voll | C33: ='Project setup'!F90 -> float | D33: ='Project setup'!G90 -> EUR/MWh | E33: ='Project setup'!H90 -> 5002 | F33: ='Project setup'!I90 -> 5002 | G33: ='Project setup'!J90 -> 5002 | H33: ='Project setup'!K90 -> 5002 | ... N33: ='Project setup'!Q90 -> 0
A34: ='Project setup'!D95 -> DEMAND_INF_PUB | B34: ='Project setup'!E95 -> demand_inf_pub_py | C34: ='Project setup'!F95 -> int | D34: ='Project setup'!G95 -> Year | E34: ='Project setup'!H95 -> 2020 | F34: ='Project setup'!I95 -> 2020 | G34: ='Project setup'!J95 -> 2020 | H34: ='Project setup'!K95 -> 2020 | ... N34: ='Project setup'!Q95 -> 0
A35: ='Project setup'!D96 -> DEMAND_INF_PUB | B35: ='Project setup'!E96 -> demand_inf_pub_amount_file | C35: ='Project setup'!F96 -> str | D35: ='Project setup'!G96 -> - | E35: ='Project setup'!H96 -> TYNDP_2024_National_Trends | F35: ='Project setup'!I96 -> TYNDP_2024_National_Trends | G35: ='Project setup'!J96 -> TYNDP_2024_National_Trends | H35: ='Project setup'!K96 -> TYNDP_2024_National_Trends | ... N35: ='Project setup'!Q96 -> 0
A36: ='Project setup'!D97 -> DEMAND_INF_PUB | B36: ='Project setup'!E97 -> demand_inf_pub_voll | C36: ='Project setup'!F97 -> float | D36: ='Project setup'!G97 -> EUR/MWh | E36: ='Project setup'!H97 -> 5003 | F36: ='Project setup'!I97 -> 5003 | G36: ='Project setup'!J97 -> 5003 | H36: ='Project setup'!K97 -> 5003 | ... N36: ='Project setup'!Q97 -> 0
A37: ='Project setup'!D102 -> DEMAND_INF_EV | B37: ='Project setup'!E102 -> demand_inf_ev_py | C37: ='Project setup'!F102 -> int | D37: ='Project setup'!G102 -> Year | E37: ='Project setup'!H102 -> 2020 | F37: ='Project setup'!I102 -> 2020 | G37: ='Project setup'!J102 -> 2020 | H37: ='Project setup'!K102 -> 2020 | ... N37: ='Project setup'!Q102 -> 0
A38: ='Project setup'!D103 -> DEMAND_INF_EV | B38: ='Project setup'!E103 -> demand_inf_ev_amount_file | C38: ='Project setup'!F103 -> str | D38: ='Project setup'!G103 -> - | E38: ='Project setup'!H103 -> TYNDP_2024_National_Trends | F38: ='Project setup'!I103 -> TYNDP_2024_National_Trends | G38: ='Project setup'!J103 -> TYNDP_2024_National_Trends | H38: ='Project setup'!K103 -> TYNDP_2024_National_Trends | ... N38: ='Project setup'!Q103 -> 0
A39: ='Project setup'!D104 -> DEMAND_INF_EV | B39: ='Project setup'!E104 -> demand_inf_ev_voll | C39: ='Project setup'!F104 -> float | D39: ='Project setup'!G104 -> EUR/MWh | E39: ='Project setup'!H104 -> 5004 | F39: ='Project setup'!I104 -> 5004 | G39: ='Project setup'!J104 -> 5004 | H39: ='Project setup'!K104 -> 5004 | ... N39: ='Project setup'!Q104 -> 0
A40: ='Project setup'!D111 -> DEMAND_FLEX_CLA | B40: ='Project setup'!E111 -> demand_flex_cla_amount_file | C40: ='Project setup'!F111 -> str | D40: ='Project setup'!G111 -> - | E40: ='Project setup'!H111 -> TYNDP_2024_National_Trends | F40: ='Project setup'!I111 -> TYNDP_2024_National_Trends | G40: ='Project setup'!J111 -> TYNDP_2024_National_Trends | H40: ='Project setup'!K111 -> TYNDP_2024_National_Trends | ... N40: ='Project setup'!Q111 -> 0
...
